Workbook

Sheet Sheet1

Sheet Assumptions
B1: ASSUMPTIONS | F1: Consolidated | All figures in ₹ Crores
B3: Year | C3: 2025 | D3: =C3+1 -> 2026 | E3: =D3+1 -> 2027 | F3: =E3+1 -> 2028 | G3: =F3+1 -> 2029 | H3: =G3+1 -> 2030
B5: INCOME STATEMENT ASSUMPTIONS
B6: Revenue Growth Rate (%) | D6: 0.12 | E6: 0.11 | F6: 0.1 | G6: 0.1 | H6: 0.09
B7: COGS (Manufacturing) as % of Revenue | C7: 0.62 | D7: 0.62 | E7: 0.615 | F7: 0.61 | G7: 0.605 | H7: 0.605
B8: SG&A / Operating Expenses as % of Revenue | C8: 0.21 | D8: 0.205 | E8: 0.2 | F8: 0.195 | G8: 0.2 | H8: 0.205
B9: Other Income (₹ Cr) | C9: 397 | D9: 420 | E9: 440 | F9: 460 | G9: 480 | H9: 500
B10: Effective Tax Rate (%) | C10: 0.2 | D10: 0.25 | E10: 0.25 | F10: 0.25 | G10: 0.25 | H10: 0.25
B11: Dividend Payout Ratio (%) | C11: 0.38 | D11: 0.38 | E11: 0.35 | F11: 0.33 | G11: 0.3 | H11: 0.3
B13: DEPRECIATION & CAPEX ASSUMPTIONS
B14: Depreciation Rate (% of Opening Gross Block) | D14: 0.04 | E14: 0.042 | F14: 0.043 | G14: 0.045 | H14: 0.045
B15: Capital Expenditure – Gross Block Additions (₹ Cr) | D15: 12000 | E15: 12000 | F15: 10000 | G15: 10000 | H15: 8000
B16: Asset Disposals at Cost (₹ Cr) | D16: 0 | E16: 0 | F16: 500 | G16: 500 | H16: 500
B17: CWIP Closing Balance (₹ Cr) | C17: 6234 | D17: 7000 | E17: 7000 | F17: 6000 | G17: 5000 | H17: 4000
B19: DEBT & FINANCING ASSUMPTIONS
B20: Interest Rate on Total Debt (Annual %) | D20: 0.075 | E20: 0.075 | F20: 0.075 | G20: 0.075 | H20: 0.075
B21: New Debt Raised (₹ Cr) | D21: 5000 | E21: 3000 | F21: 0 | G21: 0 | H21: 0
B22: Debt Repayments (₹ Cr) | D22: 2000 | E22: 3000 | F22: 3000 | G22: 3000 | H22: 3000
B23: New Equity Issued (₹ Cr) | D23: 0 | E23: 0 | F23: 0 | G23: 0 | H23: 0
B24: Share Buybacks (₹ Cr) | D24: 0 | E24: 0 | F24: 0 | G24: 0 | H24: 0
B26: WORKING CAPITAL ASSUMPTIONS
B27: Accounts Receivable Days (on Revenue) | C27: 28 | D27: 27 | E27: 26 | F27: 25 | G27: 25 | H27: 25
B28: Inventory Days (on COGS) | C28: 45 | D28: 45 | E28: 43 | F28: 42 | G28: 42 | H28: 42
B29: Accounts Payable Days (on COGS) | C29: 58 | D29: 57 | E29: 55 | F29: 55 | G29: 55 | H29: 55
B30: Other Current Assets (% of Revenue) | C30: 0.066 | D30: 0.065 | E30: 0.063 | F30: 0.06 | G30: 0.06 | H30: 0.06
B31: Other Current Liabilities (% of Revenue) | C31: 0.105 | D31: 0.105 | E31: 0.103 | F31: 0.1 | G31: 0.1 | H31: 0.1
B33: BALANCE SHEET ASSUMPTIONS
B34: Investments – Closing Balance (₹ Cr) | C34: 5156 | D34: 5500 | E34: 5500 | F34: 5000 | G34: 5000 | H34: 5000
B35: LT Other Liabilities (Def. Tax, Provisions) (₹ Cr) | C35: 23366 | D35: 23366 | E35: 23366 | F35: 23366 | G35: 23366 | H35: 23366
B36: LT Other Assets (Def. Tax Assets, Intangibles) (₹ Cr) | C36: 8529 | D36: 8529 | E36: 8529 | F36: 8529 | G36: 8529 | H36: 8529
B37: Short-Term Debt – Fixed Portion (₹ Cr) | C37: 4102 | D37: 4102 | E37: 4102 | F37: 4102 | G37: 4102 | H37: 4102
B39: FY2025 HISTORICAL REFERENCE – DEPRECIATION SCHEDULE BASE
B40: FY2025 Closing Gross Block (₹ Cr) | C40: 115000
B41: FY2025 Closing Accumulated Depreciation (₹ Cr) | C41: 20436

Sheet Income Statement
B1: INCOME STATEMENT | F1: Consolidated | All figures in ₹ Crores
B3: Year | C3: 2025 | D3: =C3+1 -> 2026 | E3: =D3+1 -> 2027 | F3: =E3+1 -> 2028 | G3: =F3+1 -> 2029 | H3: =G3+1 -> 2030
B5: Revenue | C5: 75955 | D5: ='Income Statement'!C5*(1+Assumptions!D6) -> 85069.6 | E5: ='Income Statement'!D5*(1+Assumptions!E6) -> 94427.256 | F5: ='Income Statement'!E5*(1+Assumptions!F6) -> 103869.98 | G5: ='Income Statement'!F5*(1+Assumptions!G6) -> 114256.98 | H5: ='Income Statement'!G5*(1+Assumptions!H6) -> 124540.11
B6: Cost of Goods Sold | C6: 47092 | D6: ='Income Statement'!D5*Assumptions!D7 -> 52743.152 | E6: ='Income Statement'!E5*Assumptions!E7 -> 58072.762 | F6: ='Income Statement'!F5*Assumptions!F7 -> 63360.689 | G6: ='Income Statement'!G5*Assumptions!G7 -> 69125.473 | H6: ='Income Statement'!H5*Assumptions!H7 -> 75346.765
B7: Gross Profit | C7: =C5-C6 -> 28863 | D7: ='Income Statement'!D5-'Income Statement'!D6 -> 32326.448 | E7: ='Income Statement'!E5-'Income Statement'!E6 -> 36354.494 | F7: ='Income Statement'!F5-'Income Statement'!F6 -> 40509.293 | G7: ='Income Statement'!G5-'Income Statement'!G6 -> 45131.507 | H7: ='Income Statement'!H5-'Income Statement'!H6 -> 49193.343
B8: SG&A / Operating Expenses | C8: 16066 | D8: ='Income Statement'!D5*Assumptions!D8 -> 17439.268 | E8: ='Income Statement'!E5*Assumptions!E8 -> 18885.451 | F8: ='Income Statement'!F5*Assumptions!F8 -> 20254.646 | G8: ='Income Statement'!G5*Assumptions!G8 -> 22851.396 | H8: ='Income Statement'!H5*Assumptions!H8 -> 25530.722
B9: EBITDA | C9: ='Income Statement'!C7-'Income Statement'!C8 -> 12797 | D9: ='Income Statement'!D7-'Income Statement'!D8 -> 14887.18 | E9: ='Income Statement'!E7-'Income Statement'!E8 -> 17469.042 | F9: ='Income Statement'!F7-'Income Statement'!F8 -> 20254.646 | G9: ='Income Statement'!G7-'Income Statement'!G8 -> 22280.111 | H9: ='Income Statement'!H7-'Income Statement'!H8 -> 23662.621
B10: EBITDA Margin (%) | C10: 0.1704 | D10: ='Income Statement'!D9/'Income Statement'!D5 -> 0.175 | E10: ='Income Statement'!E9/'Income Statement'!E5 -> 0.185 | F10: ='Income Statement'!F9/'Income Statement'!F5 -> 0.195 | G10: ='Income Statement'!G9/'Income Statement'!G5 -> 0.195 | H10: ='Income Statement'!H9/'Income Statement'!H5 -> 0.19
B11: Depreciation & Amortization (D&A) | C11: 4015 | D11: =Schedules!D27 -> 4600 | E11: =Schedules!E27 -> 5334 | F11: =Schedules!F27 -> 5977 | G11: =Schedules!G27 -> 6682.5 | H11: =Schedules!H27 -> 7110
B12: EBIT | C12: 8782 | D12: ='Income Statement'!D9-'Income Statement'!D11 -> 10287.18 | E12: ='Income Statement'!E9-'Income Statement'!E11 -> 12135.042 | F12: ='Income Statement'!F9-'Income Statement'!F11 -> 14277.646 | G12: ='Income Statement'!G9-'Income Statement'!G11 -> 15597.611 | H12: ='Income Statement'!H9-'Income Statement'!H11 -> 16552.621
B13: Other Income | C13: 397 | D13: =Assumptions!D9 -> 420 | E13: =Assumptions!E9 -> 440 | F13: =Assumptions!F9 -> 460 | G13: =Assumptions!G9 -> 480 | H13: =Assumptions!H9 -> 500
B14: Interest Expense | C14: 1651 | D14: =Schedules!D14 -> 1920.15 | E14: =Schedules!E14 -> 2032.65 | F14: =Schedules!F14 -> 1920.15 | G14: =Schedules!G14 -> 1695.15 | H14: =Schedules!H14 -> 1470.15
B15: Profit Before Tax (PBT) | C15: 7528 | D15: ='Income Statement'!D12+'Income Statement'!D13-'Income Statement'!D14 -> 8787.03 | E15: ='Income Statement'!E12+'Income Statement'!E13-'Income Statement'!E14 -> 10542.392 | F15: ='Income Statement'!F12+'Income Statement'!F13-'Income Statement'!F14 -> 12817.496 | G15: ='Income Statement'!G12+'Income Statement'!G13-'Income Statement'!G14 -> 14382.461 | H15: ='Income Statement'!H12+'Income Statement'!H13-'Income Statement'!H14 -> 15582.471
B16: Income Tax | C16: 1488 | D16: ='Income Statement'!D15*Assumptions!D10 -> 2196.7575 | E16: ='Income Statement'!E15*Assumptions!E10 -> 2635.5981 | F16: ='Income Statement'!F15*Assumptions!F10 -> 3204.3741 | G16: ='Income Statement'!G15*Assumptions!G10 -> 3595.6153 | H16: ='Income Statement'!H15*Assumptions!H10 -> 3895.6176
B17: Net Income (PAT) | C17: 6040 | D17: ='Income Statement'!D15-'Income Statement'!D16 -> 6590.2725 | E17: ='Income Statement'!E15-'Income Statement'!E16 -> 7906.7943 | F17: ='Income Statement'!F15-'Income Statement'!F16 -> 9613.1223 | G17: ='Income Statement'!G15-'Income Statement'!G16 -> 10786.846 | H17: ='Income Statement'!H15-'Income Statement'!H16 -> 11686.853
B18: Effective Tax Rate (%) | C18: 0.1977 | D18: ='Income Statement'!D16/'Income Statement'!D15 -> 0.25 | E18: ='Income Statement'!E16/'Income Statement'!E15 -> 0.25 | F18: ='Income Statement'!F16/'Income Statement'!F15 -> 0.25 | G18: ='Income Statement'!G16/'Income Statement'!G15 -> 0.25 | H18: ='Income Statement'!H16/'Income Statement'!H15 -> 0.25
B19: Net Profit Margin (%) | C19: 0.0796 | D19: ='Income Statement'!D17/'Income Statement'!D5 -> 0.077469184 | E19: ='Income Statement'!E17/'Income Statement'!E5 -> 0.083734237 | F19: ='Income Statement'!F17/'Income Statement'!F5 -> 0.092549572 | G19: ='Income Statement'!G17/'Income Statement'!G5 -> 0.094408638 | H19: ='Income Statement'!H17/'Income Statement'!H5 -> 0.093840073

Sheet Balance Sheet
B1: BALANCE SHEET | F1: Consolidated | All figures in ₹ Crores
B3: Year | C3: 2025 | D3: =C3+1 -> 2026 | E3: =D3+1 -> 2027 | F3: =E3+1 -> 2028 | G3: =F3+1 -> 2029 | H3: =G3+1 -> 2030
B5: ASSETS
B7: CURRENT ASSETS
B8: Cash & Cash Equivalents | C8: 2500 | D8: ='Cash Flow'!D35 -> 1111.9547 | E8: ='Cash Flow'!E35 -> -298.60811 | F8: ='Cash Flow'!F35 -> 956.2762 | G8: ='Cash Flow'!G35 -> 3098.931 | H8: ='Cash Flow'!H35 -> 8318.3096
B9: Accounts Receivable | C9: 5831 | D9: =Schedules!D41 -> 6292.8197 | E9: =Schedules!E41 -> 6726.3251 | F9: =Schedules!F41 -> 7114.3823 | G9: =Schedules!G41 -> 7825.8205 | H9: =Schedules!H41 -> 8530.1444
B10: Inventory (Raw Materials, WIP, FG) | C10: 5805 | D10: =Schedules!D42 -> 6502.5804 | E10: =Schedules!E42 -> 6841.4487 | F10: =Schedules!F42 -> 7290.819 | G10: =Schedules!G42 -> 7954.164 | H10: =Schedules!H42 -> 8670.0387
B11: Other Current Assets | C11: 5013 | D11: =Schedules!D43 -> 5529.524 | E11: =Schedules!E43 -> 5948.9171 | F11: =Schedules!F43 -> 6232.1989 | G11: =Schedules!G43 -> 6855.4188 | H11: =Schedules!H43 -> 7472.4065
B12: TOTAL CURRENT ASSETS | C12: 19149 | D12: =SUM('Balance Sheet'!D8:D11) -> 19436.879 | E12: =SUM('Balance Sheet'!E8:E11) -> 19218.083 | F12: =SUM('Balance Sheet'!F8:F11) -> 21593.676 | G12: =SUM('Balance Sheet'!G8:G11) -> 25734.334 | H12: =SUM('Balance Sheet'!H8:H11) -> 32990.899
B14: NON-CURRENT ASSETS
B15: Net Property, Plant & Equipment (Net PPE) | C15: 94564 | D15: =Schedules!D32 -> 101964 | E15: =Schedules!E32 -> 108630 | F15: =Schedules!F32 -> 112653 | G15: =Schedules!G32 -> 115970.5 | H15: =Schedules!H32 -> 116860.5
B16: Capital Work-in-Progress (CWIP) | C16: 6234 | D16: =Assumptions!D17 -> 7000 | E16: =Assumptions!E17 -> 7000 | F16: =Assumptions!F17 -> 6000 | G16: =Assumptions!G17 -> 5000 | H16: =Assumptions!H17 -> 4000
B17: Investments | C17: 5156 | D17: =Assumptions!D34 -> 5500 | E17: =Assumptions!E34 -> 5500 | F17: =Assumptions!F34 -> 5000 | G17: =Assumptions!G34 -> 5000 | H17: =Assumptions!H34 -> 5000
B18: Other Non-Current Assets | C18: 8529 | D18: =Assumptions!D36 -> 8529 | E18: =Assumptions!E36 -> 8529 | F18: =Assumptions!F36 -> 8529 | G18: =Assumptions!G36 -> 8529 | H18: =Assumptions!H36 -> 8529
B19: TOTAL NON-CURRENT ASSETS | C19: 114483 | D19: =SUM('Balance Sheet'!D15:D18) -> 122993 | E19: =SUM('Balance Sheet'!E15:E18) -> 129659 | F19: =SUM('Balance Sheet'!F15:F18) -> 132182 | G19: =SUM('Balance Sheet'!G15:G18) -> 134499.5 | H19: =SUM('Balance Sheet'!H15:H18) -> 134389.5
B21: TOTAL ASSETS | C21: 133632 | D21: ='Balance Sheet'!D12+'Balance Sheet'!D19 -> 142429.88 | E21: ='Balance Sheet'!E12+'Balance Sheet'!E19 -> 148877.08 | F21: ='Balance Sheet'!F12+'Balance Sheet'!F19 -> 153775.68 | G21: ='Balance Sheet'!G12+'Balance Sheet'!G19 -> 160233.83 | H21: ='Balance Sheet'!H12+'Balance Sheet'!H19 -> 167380.4
B23: LIABILITIES & SHAREHOLDERS' EQUITY
B25: CURRENT LIABILITIES
B26: Accounts Payable | C26: 7482 | D26: =Schedules!D47 -> 8236.6018 | E26: =Schedules!E47 -> 8750.6902 | F26: =Schedules!F47 -> 9547.501 | G26: =Schedules!G47 -> 10416.167 | H26: =Schedules!H47 -> 11353.622
B27: Short-Term Debt | C27: 4102 | D27: =Assumptions!D37 -> 4102 | E27: =Assumptions!E37 -> 4102 | F27: =Assumptions!F37 -> 4102 | G27: =Assumptions!G37 -> 4102 | H27: =Assumptions!H37 -> 4102
B28: Other Current Liabilities | C28: 7975 | D28: =Schedules!D48 -> 8932.308 | E28: =Schedules!E48 -> 9726.0074 | F28: =Schedules!F48 -> 10386.998 | G28: =Schedules!G48 -> 11425.698 | H28: =Schedules!H48 -> 12454.011
B29: TOTAL CURRENT LIABILITIES | C29: 19559 | D29: =SUM('Balance Sheet'!D26:D28) -> 21270.91 | E29: =SUM('Balance Sheet'!E26:E28) -> 22578.698 | F29: =SUM('Balance Sheet'!F26:F28) -> 24036.499 | G29: =SUM('Balance Sheet'!G26:G28) -> 25943.865 | H29: =SUM('Balance Sheet'!H26:H28) -> 27909.633
B31: NON-CURRENT LIABILITIES
B32: Long-Term Debt | C32: 20000 | D32: =Schedules!D9-Assumptions!D37 -> 23000 | E32: =Schedules!E9-Assumptions!E37 -> 23000 | F32: =Schedules!F9-Assumptions!F37 -> 20000 | G32: =Schedules!G9-Assumptions!G37 -> 17000 | H32: =Schedules!H9-Assumptions!H37 -> 14000
B33: Other LT Liabilities | C33: 23366 | D33: =Assumptions!D35 -> 23366 | E33: =Assumptions!E35 -> 23366 | F33: =Assumptions!F35 -> 23366 | G33: =Assumptions!G35 -> 23366 | H33: =Assumptions!H35 -> 23366
B34: TOTAL NON-CURRENT LIABILITIES | C34: 43366 | D34: ='Balance Sheet'!D32+'Balance Sheet'!D33 -> 46366 | E34: ='Balance Sheet'!E32+'Balance Sheet'!E33 -> 46366 | F34: ='Balance Sheet'!F32+'Balance Sheet'!F33 -> 43366 | G34: ='Balance Sheet'!G32+'Balance Sheet'!G33 -> 40366 | H34: ='Balance Sheet'!H32+'Balance Sheet'!H33 -> 37366
B36: SHAREHOLDERS' EQUITY
B37: Share Capital | C37: 295 | D37: =Schedules!D65 -> 295 | E37: =Schedules!E65 -> 295 | F37: =Schedules!F65 -> 295 | G37: =Schedules!G65 -> 295 | H37: =Schedules!H65 -> 295
B38: Retained Earnings & Reserves | C38: 70412 | D38: =Schedules!D71 -> 74497.969 | E38: =Schedules!E71 -> 79637.385 | F38: =Schedules!F71 -> 86078.177 | G38: =Schedules!G71 -> 93628.969 | H38: =Schedules!H71 -> 101809.77
B39: TOTAL SHAREHOLDERS' EQUITY | C39: 70707 | D39: =Schedules!D74 -> 74792.969 | E39: =Schedules!E74 -> 79932.385 | F39: =Schedules!F74 -> 86373.177 | G39: =Schedules!G74 -> 93923.969 | H39: =Schedules!H74 -> 102104.77
B41: TOTAL LIABILITIES & EQUITY | C41: 133632 | D41: ='Balance Sheet'!D29+'Balance Sheet'!D34+'Balance Sheet'!D39 -> 142429.88 | E41: ='Balance Sheet'!E29+'Balance Sheet'!E34+'Balance Sheet'!E39 -> 148877.08 | F41: ='Balance Sheet'!F29+'Balance Sheet'!F34+'Balance Sheet'!F39 -> 153775.68 | G41: ='Balance Sheet'!G29+'Balance Sheet'!G34+'Balance Sheet'!G39 -> 160233.83 | H41: ='Balance Sheet'!H29+'Balance Sheet'!H34+'Balance Sheet'!H39 -> 167380.4
B43: BALANCE CHECK | C43: 0 | D43: ='Balance Sheet'!D21-'Balance Sheet'!D41 -> 0 | E43: ='Balance Sheet'!E21-'Balance Sheet'!E41 -> 0 | F43: ='Balance Sheet'!F21-'Balance Sheet'!F41 -> 0 | G43: ='Balance Sheet'!G21-'Balance Sheet'!G41 -> 0 | H43: ='Balance Sheet'!H21-'Balance Sheet'!H41 -> 0

Sheet Schedules
B1: SUPPORTING SCHEDULES | F1: Consolidated | All figures in ₹ Crores
B3: Year | C3: 2025 | D3: =C3+1 -> 2026 | E3: =D3+1 -> 2027 | F3: =E3+1 -> 2028 | G3: =F3+1 -> 2029 | H3: =G3+1 -> 2030
B5: DEBT SCHEDULE
B6: Opening Total Debt Balance | D6: =Schedules!C9 -> 24102 | E6: =Schedules!D9 -> 27102 | F6: =Schedules!E9 -> 27102 | G6: =Schedules!F9 -> 24102 | H6: =Schedules!G9 -> 21102
A7: + | B7: New Borrowings | D7: =Assumptions!D21 -> 5000 | E7: =Assumptions!E21 -> 3000 | F7: =Assumptions!F21 -> 0 | G7: =Assumptions!G21 -> 0 | H7: =Assumptions!H21 -> 0
A8: - | B8: Debt Repayments | D8: =Assumptions!D22 -> 2000 | E8: =Assumptions!E22 -> 3000 | F8: =Assumptions!F22 -> 3000 | G8: =Assumptions!G22 -> 3000 | H8: =Assumptions!H22 -> 3000
B9: Closing Total Debt Balance | C9: 24102 | D9: =Schedules!D6+Schedules!D7-Schedules!D8 -> 27102 | E9: =Schedules!E6+Schedules!E7-Schedules!E8 -> 27102 | F9: =Schedules!F6+Schedules!F7-Schedules!F8 -> 24102 | G9: =Schedules!G6+Schedules!G7-Schedules!G8 -> 21102 | H9: =Schedules!H6+Schedules!H7-Schedules!H8 -> 18102
B11: Interest Calculation
B12: Interest Rate (Annual %) | D12: =Assumptions!D20 -> 0.075 | E12: =Assumptions!E20 -> 0.075 | F12: =Assumptions!F20 -> 0.075 | G12: =Assumptions!G20 -> 0.075 | H12: =Assumptions!H20 -> 0.075
B13: Average Debt Balance [(Opening + Closing) / 2] | D13: =(Schedules!D6+Schedules!D9)/2 -> 25602 | E13: =(Schedules!E6+Schedules!E9)/2 -> 27102 | F13: =(Schedules!F6+Schedules!F9)/2 -> 25602 | G13: =(Schedules!G6+Schedules!G9)/2 -> 22602 | H13: =(Schedules!H6+Schedules!H9)/2 -> 19602
B14: Interest Expense for the Year | D14: =Schedules!D13*Schedules!D12 -> 1920.15 | E14: =Schedules!E13*Schedules!E12 -> 2032.65 | F14: =Schedules!F13*Schedules!F12 -> 1920.15 | G14: =Schedules!G13*Schedules!G12 -> 1695.15 | H14: =Schedules!H13*Schedules!H12 -> 1470.15
B17: DEPRECIATION & AMORTIZATION SCHEDULE
B19: GROSS BLOCK (Cost of Fixed Assets)
B20: Opening Gross Block | D20: =Assumptions!C40 -> 115000 | E20: =Schedules!D23 -> 127000 | F20: =Schedules!E23 -> 139000 | G20: =Schedules!F23 -> 148500 | H20: =Schedules!G23 -> 158000
A21: + | B21: Capital Expenditure | D21: =Assumptions!D15 -> 12000 | E21: =Assumptions!E15 -> 12000 | F21: =Assumptions!F15 -> 10000 | G21: =Assumptions!G15 -> 10000 | H21: =Assumptions!H15 -> 8000
A22: - | B22: Asset Disposals | D22: =Assumptions!D16 -> 0 | E22: =Assumptions!E16 -> 0 | F22: =Assumptions!F16 -> 500 | G22: =Assumptions!G16 -> 500 | H22: =Assumptions!H16 -> 500
B23: Closing Gross Block | C23: 115000 | D23: =Schedules!D20+Schedules!D21-Schedules!D22 -> 127000 | E23: =Schedules!E20+Schedules!E21-Schedules!E22 -> 139000 | F23: =Schedules!F20+Schedules!F21-Schedules!F22 -> 148500 | G23: =Schedules!G20+Schedules!G21-Schedules!G22 -> 158000 | H23: =Schedules!H20+Schedules!H21-Schedules!H22 -> 165500
B25: ACCUMULATED DEPRECIATION
B26: Opening Accumulated Depreciation | D26: =Assumptions!C41 -> 20436 | E26: =Schedules!D29 -> 25036 | F26: =Schedules!E29 -> 30370 | G26: =Schedules!F29 -> 35847 | H26: =Schedules!G29 -> 42029.5
A27: + | B27: Depreciation Charge for the Year | D27: =Assumptions!D14*Schedules!D20 -> 4600 | E27: =Assumptions!E14*Schedules!E20 -> 5334 | F27: =Assumptions!F14*Schedules!F20 -> 5977 | G27: =Assumptions!G14*Schedules!G20 -> 6682.5 | H27: =Assumptions!H14*Schedules!H20 -> 7110
A28: - | B28: Acc. Depr. on Disposed Assets | D28: =Schedules!D22 -> 0 | E28: =Schedules!E22 -> 0 | F28: =Schedules!F22 -> 500 | G28: =Schedules!G22 -> 500 | H28: =Schedules!H22 -> 500
B29: Closing Accumulated Depreciation | C29: 20436 | D29: =Schedules!D26+Schedules!D27-Schedules!D28 -> 25036 | E29: =Schedules!E26+Schedules!E27-Schedules!E28 -> 30370 | F29: =Schedules!F26+Schedules!F27-Schedules!F28 -> 35847 | G29: =Schedules!G26+Schedules!G27-Schedules!G28 -> 42029.5 | H29: =Schedules!H26+Schedules!H27-Schedules!H28 -> 48639.5
B31: NET FIXED ASSETS
B32: Net PPE (Closing Gross Block – Closing Acc. Depr.) | C32: 94564 | D32: =Schedules!D23-Schedules!D29 -> 101964 | E32: =Schedules!E23-Schedules!E29 -> 108630 | F32: =Schedules!F23-Schedules!F29 -> 112653 | G32: =Schedules!G23-Schedules!G29 -> 115970.5 | H32: =Schedules!H23-Schedules!H29 -> 116860.5
B35: WORKING CAPITAL SCHEDULE
B37: Revenue | C37: 75955 | D37: ='Income Statement'!D5 -> 85069.6 | E37: ='Income Statement'!E5 -> 94427.256 | F37: ='Income Statement'!F5 -> 103869.98 | G37: ='Income Statement'!G5 -> 114256.98 | H37: ='Income Statement'!H5 -> 124540.11
B38: COGS | C38: 47092 | D38: ='Income Statement'!D6 -> 52743.152 | E38: ='Income Statement'!E6 -> 58072.762 | F38: ='Income Statement'!F6 -> 63360.689 | G38: ='Income Statement'!G6 -> 69125.473 | H38: ='Income Statement'!H6 -> 75346.765
B40: CURRENT ASSETS
B41: Accounts Receivable [= Revenue × AR Days / 365] | C41: 5831 | D41: =Schedules!D37*Assumptions!D27/365 -> 6292.8197 | E41: =Schedules!E37*Assumptions!E27/365 -> 6726.3251 | F41: =Schedules!F37*Assumptions!F27/365 -> 7114.3823 | G41: =Schedules!G37*Assumptions!G27/365 -> 7825.8205 | H41: =Schedules!H37*Assumptions!H27/365 -> 8530.1444
B42: Inventory [= COGS × Inventory Days / 365] | C42: 5805 | D42: =Schedules!D38*Assumptions!D28/365 -> 6502.5804 | E42: =Schedules!E38*Assumptions!E28/365 -> 6841.4487 | F42: =Schedules!F38*Assumptions!F28/365 -> 7290.819 | G42: =Schedules!G38*Assumptions!G28/365 -> 7954.164 | H42: =Schedules!H38*Assumptions!H28/365 -> 8670.0387
B43: Other Current Assets [= Revenue × % Assumption] | C43: 5013 | D43: =Schedules!D37*Assumptions!D30 -> 5529.524 | E43: =Schedules!E37*Assumptions!E30 -> 5948.9171 | F43: =Schedules!F37*Assumptions!F30 -> 6232.1989 | G43: =Schedules!G37*Assumptions!G30 -> 6855.4188 | H43: =Schedules!H37*Assumptions!H30 -> 7472.4065
B44: Total Current Assets | C44: 16649 | D44: =SUM(Schedules!D41:D43) -> 18324.924 | E44: =SUM(Schedules!E41:E43) -> 19516.691 | F44: =SUM(Schedules!F41:F43) -> 20637.4 | G44: =SUM(Schedules!G41:G43) -> 22635.403 | H44: =SUM(Schedules!H41:H43) -> 24672.59
B46: CURRENT LIABILITIES
B47: Accounts Payable [= COGS × AP Days / 365] | C47: 7482 | D47: =Schedules!D38*Assumptions!D29/365 -> 8236.6018 | E47: =Schedules!E38*Assumptions!E29/365 -> 8750.6902 | F47: =Schedules!F38*Assumptions!F29/365 -> 9547.501 | G47: =Schedules!G38*Assumptions!G29/365 -> 10416.167 | H47: =Schedules!H38*Assumptions!H29/365 -> 11353.622
B48: Other Current Liabilities [= Revenue × % Assumption] | C48: 7975 | D48: =Schedules!D37*Assumptions!D31 -> 8932.308 | E48: =Schedules!E37*Assumptions!E31 -> 9726.0074 | F48: =Schedules!F37*Assumptions!F31 -> 10386.998 | G48: =Schedules!G37*Assumptions!G31 -> 11425.698 | H48: =Schedules!H37*Assumptions!H31 -> 12454.011
B49: Total Current Liabilities | C49: 15457 | D49: =SUM(Schedules!D47:D48) -> 17168.91 | E49: =SUM(Schedules!E47:E48) -> 18476.698 | F49: =SUM(Schedules!F47:F48) -> 19934.499 | G49: =SUM(Schedules!G47:G48) -> 21841.865 | H49: =SUM(Schedules!H47:H48) -> 23807.633
B51: Year-on-Year Changes in Working Capital (for CFS)
B52: (Increase)/Decrease in Accounts Receivable | D52: =-(Schedules!D41-Schedules!C41) -> -461.81973 | E52: =-(Schedules!E41-Schedules!D41) -> -433.50536 | F52: =-(Schedules!F41-Schedules!E41) -> -388.05722 | G52: =-(Schedules!G41-Schedules!F41) -> -711.43823 | H52: =-(Schedules!H41-Schedules!G41) -> -704.32385
B53: (Increase)/Decrease in Inventory | D53: =-(Schedules!D42-Schedules!C42) -> -697.58038 | E53: =-(Schedules!E42-Schedules!D42) -> -338.86834 | F53: =-(Schedules!F42-Schedules!E42) -> -449.37026 | G53: =-(Schedules!G42-Schedules!F42) -> -663.34501 | H53: =-(Schedules!H42-Schedules!G42) -> -715.87476
B54: (Increase)/Decrease in Other Current Assets | D54: =-(Schedules!D43-Schedules!C43) -> -516.524 | E54: =-(Schedules!E43-Schedules!D43) -> -419.39313 | F54: =-(Schedules!F43-Schedules!E43) -> -283.28177 | G54: =-(Schedules!G43-Schedules!F43) -> -623.21989 | H54: =-(Schedules!H43-Schedules!G43) -> -616.98769
...

Sheet Cash Flow
B1: CASH FLOW STATEMENT | F1: Consolidated | All figures in ₹ Crores
B3: Year | C3: 2025 | D3: =C3+1 -> 2026 | E3: =D3+1 -> 2027 | F3: =E3+1 -> 2028 | G3: =F3+1 -> 2029 | H3: =G3+1 -> 2030
B5: CASH FLOWS FROM OPERATING ACTIVITIES
B6: Net Income | C6: 6040 | D6: ='Income Statement'!D17 -> 6590.2725 | E6: ='Income Statement'!E17 -> 7906.7943 | F6: ='Income Statement'!F17 -> 9613.1223 | G6: ='Income Statement'!G17 -> 10786.846 | H6: ='Income Statement'!H17 -> 11686.853
A7: + | B7: Depreciation & Amortization | C7: 4015 | D7: =Schedules!D27 -> 4600 | E7: =Schedules!E27 -> 5334 | F7: =Schedules!F27 -> 5977 | G7: =Schedules!G27 -> 6682.5 | H7: =Schedules!H27 -> 7110
B8: Changes in Working Capital:
B9: (Increase)/Decrease in Accounts Receivable | C9: 0 | D9: =Schedules!D52 -> -461.81973 | E9: =Schedules!E52 -> -433.50536 | F9: =Schedules!F52 -> -388.05722 | G9: =Schedules!G52 -> -711.43823 | H9: =Schedules!H52 -> -704.32385
B10: (Increase)/Decrease in Inventory | C10: 0 | D10: =Schedules!D53 -> -697.58038 | E10: =Schedules!E53 -> -338.86834 | F10: =Schedules!F53 -> -449.37026 | G10: =Schedules!G53 -> -663.34501 | H10: =Schedules!H53 -> -715.87476
B11: (Increase)/Decrease in Other Current Assets | C11: 0 | D11: =Schedules!D54 -> -516.524 | E11: =Schedules!E54 -> -419.39313 | F11: =Schedules!F54 -> -283.28177 | G11: =Schedules!G54 -> -623.21989 | H11: =Schedules!H54 -> -616.98769
B12: Increase/(Decrease) in Accounts Payable | C12: 0 | D12: =Schedules!D55 -> 754.60182 | E12: =Schedules!E55 -> 514.08841 | F12: =Schedules!F55 -> 796.81082 | G12: =Schedules!G55 -> 868.66608 | H12: =Schedules!H55 -> 937.45504
B13: Increase/(Decrease) in Other Current Liabilities | C13: 0 | D13: =Schedules!D56 -> 957.308 | E13: =Schedules!E56 -> 793.69937 | F13: =Schedules!F56 -> 660.99079 | G13: =Schedules!G56 -> 1038.6998 | H13: =Schedules!H56 -> 1028.3128
B14: Net Cash from Operating Activities | C14: 10673 | D14: =SUM('Cash Flow'!D6:D7)+SUM('Cash Flow'!D9:D13) -> 11226.258 | E14: =SUM('Cash Flow'!E6:E7)+SUM('Cash Flow'!E9:E13) -> 13356.815 | F14: =SUM('Cash Flow'!F6:F7)+SUM('Cash Flow'!F9:F13) -> 15927.215 | G14: =SUM('Cash Flow'!G6:G7)+SUM('Cash Flow'!G9:G13) -> 17378.709 | H14: =SUM('Cash Flow'!H6:H7)+SUM('Cash Flow'!H9:H13) -> 18725.434
B16: CASH FLOWS FROM INVESTING ACTIVITIES
B17: Capital Expenditure (Gross Block Additions) | D17: =-Assumptions!D15 -> -12000 | E17: =-Assumptions!E15 -> -12000 | F17: =-Assumptions!F15 -> -10000 | G17: =-Assumptions!G15 -> -10000 | H17: =-Assumptions!H15 -> -8000
B18: (Increase)/Decrease in Capital Work-in-Progress (CWIP) | D18: =-(Assumptions!D17-Assumptions!C17) -> -766 | E18: =-(Assumptions!E17-Assumptions!D17) -> 0 | F18: =-(Assumptions!F17-Assumptions!E17) -> 1000 | G18: =-(Assumptions!G17-Assumptions!F17) -> 1000 | H18: =-(Assumptions!H17-Assumptions!G17) -> 1000
B19: (Increase)/Decrease in Investments | D19: =-(Assumptions!D34-Assumptions!C34) -> -344 | E19: =-(Assumptions!E34-Assumptions!D34) -> 0 | F19: =-(Assumptions!F34-Assumptions!E34) -> 500 | G19: =-(Assumptions!G34-Assumptions!F34) -> 0 | H19: =-(Assumptions!H34-Assumptions!G34) -> 0
B20: Proceeds from Asset Disposals (Net) | D20: =0 -> 0 | E20: =0 -> 0 | F20: =0 -> 0 | G20: =0 -> 0 | H20: =0 -> 0
B21: Net Cash from Investing Activities | C21: -15836 | D21: =SUM('Cash Flow'!D17:D20) -> -13110 | E21: =SUM('Cash Flow'!E17:E20) -> -12000 | F21: =SUM('Cash Flow'!F17:F20) -> -8500 | G21: =SUM('Cash Flow'!G17:G20) -> -9000 | H21: =SUM('Cash Flow'!H17:H20) -> -7000
B23: CASH FLOWS FROM FINANCING ACTIVITIES
B24: New Debt Raised | D24: =Assumptions!D21 -> 5000 | E24: =Assumptions!E21 -> 3000 | F24: =Assumptions!F21 -> 0 | G24: =Assumptions!G21 -> 0 | H24: =Assumptions!H21 -> 0
A25: - | B25: Debt Repayments | D25: =-Assumptions!D22 -> -2000 | E25: =-Assumptions!E22 -> -3000 | F25: =-Assumptions!F22 -> -3000 | G25: =-Assumptions!G22 -> -3000 | H25: =-Assumptions!H22 -> -3000
B26: New Equity Issued | D26: =Assumptions!D23 -> 0 | E26: =Assumptions!E23 -> 0 | F26: =Assumptions!F23 -> 0 | G26: =Assumptions!G23 -> 0 | H26: =Assumptions!H23 -> 0
A27: - | B27: Share Buybacks | D27: =-Assumptions!D24 -> 0 | E27: =-Assumptions!E24 -> 0 | F27: =-Assumptions!F24 -> 0 | G27: =-Assumptions!G24 -> 0 | H27: =-Assumptions!H24 -> 0
A28: - | B28: Dividends Paid to Shareholders | D28: =-(Schedules!D70) -> -2504.3036 | E28: =-(Schedules!E70) -> -2767.378 | F28: =-(Schedules!F70) -> -3172.3304 | G28: =-(Schedules!G70) -> -3236.0537 | H28: =-(Schedules!H70) -> -3506.0559
B29: Net Cash from Financing Activities | C29: 5076 | D29: =SUM('Cash Flow'!D24:D28) -> 495.69645 | E29: =SUM('Cash Flow'!E24:E28) -> -2767.378 | F29: =SUM('Cash Flow'!F24:F28) -> -6172.3304 | G29: =SUM('Cash Flow'!G24:G28) -> -6236.0537 | H29: =SUM('Cash Flow'!H24:H28) -> -6506.0559
B31: CASH MOVEMENT SUMMARY
B33: Net Increase / (Decrease) in Cash | C33: -86 | D33: ='Cash Flow'!D14+'Cash Flow'!D21+'Cash Flow'!D29 -> -1388.0453 | E33: ='Cash Flow'!E14+'Cash Flow'!E21+'Cash Flow'!E29 -> -1410.5628 | F33: ='Cash Flow'!F14+'Cash Flow'!F21+'Cash Flow'!F29 -> 1254.8843 | G33: ='Cash Flow'!G14+'Cash Flow'!G21+'Cash Flow'!G29 -> 2142.6548 | H33: ='Cash Flow'!H14+'Cash Flow'!H21+'Cash Flow'!H29 -> 5219.3786
B34: Opening Cash & Cash Equivalents | C34: 2586 | D34: ='Cash Flow'!C35 -> 2500 | E34: ='Cash Flow'!D35 -> 1111.9547 | F34: ='Cash Flow'!E35 -> -298.60811 | G34: ='Cash Flow'!F35 -> 956.2762 | H34: ='Cash Flow'!G35 -> 3098.931
B35: Closing Cash & Cash Equivalents | C35: 2500 | D35: ='Cash Flow'!D34+'Cash Flow'!D33 -> 1111.9547 | E35: ='Cash Flow'!E34+'Cash Flow'!E33 -> -298.60811 | F35: ='Cash Flow'!F34+'Cash Flow'!F33 -> 956.2762 | G35: ='Cash Flow'!G34+'Cash Flow'!G33 -> 3098.931 | H35: ='Cash Flow'!H34+'Cash Flow'!H33 -> 8318.3096

Sheet Ratios
B1: Ratio Analysis
B3: Year | E3: 2025 | F3: =E3+1 -> 2026 | G3: =F3+1 -> 2027 | H3: =G3+1 -> 2028 | I3: =H3+1 -> 2029 | J3: =I3+1 -> 2030
B5: PROFITABILITY | D5: Industry Avg.
B6: Gross Margin | C6: Pricing power + cost efficiency
B7: EBITDA Margin | C7: Core operating profitability
B8: EBIT Margin | C8: Operating efficiency after depreciation
B9: Net Profit Margin | C9: Final profit retained
B10: ROE | C10: Return to shareholders
B11: ROA | C11: Asset utilization efficiency
B12: ROIC | C12: Capital efficiency
B14: LIQUIDITY
B15: Current Ratio | C15: Short-term solvency
B16: Quick Ratio | C16: Liquidity without inventory
B17: Cash Ratio | C17: Pure cash safety
B18: Working Capital Ratio | C18: Operating liquidity intensity
B20: LEVERAGE
B21: Debt/Equity | C21: Capital structure risk
B22: Debt/EBITDA | C22: Debt repayment capacity
B23: Net Debt/EBITDA | C23: True leverage
B24: Interest Coverage | C24: Interest servicing ability
B25: Debt Ratio | C25: Balance sheet leverage
B27: EFFICIENCY
B28: Asset Turnover | C28: Asset productivity
B29: Fixed Asset Turnover | C29: Asset utilization
B30: Inventory Turnover | C30: Stock movement speed
B31: Receivable Turnover | C31: Collection efficiency
B33: WC
B34: DSO | C34: Collection days
B35: DIO | C35: Inventory holding period
B36: DPO | C36: Supplier credit period
B37: CCC | C37: Cash lock-up duration
B39: CASH FLOW
B40: Operating CF Margin | C40: Cash profitability
B41: FCF Margin | C41: Free cash strength
B42: Cash Conversion Ratio | C42: Earnings quality
B43: Capex Ratio | C43: Reinvestment intensity
