Workbook

Sheet Assumptions
B1: ASSUMPTIONS
B3: Year | C3: 2025 | D3: 2026 | E3: 2027 | F3: 2028 | G3: 2029 | I3: Notes:
I4: Revenue forecast | Q4: Cost of Goods Sold (COGS) Forecast
B5: REVENUE ASSUMPTIONS | I5: Step 1 | J5: Industry CAGR | Q5: Step 1 | R5: Historical COGS Margin
B6: Revenue Growth % | C6: 0.08 | D6: 0.1 | E6: 0.09 | F6: 0.075 | G6: 0.065 | J6: IBEF | K6: Sector CAGR | M6: Industry CAGR Data | R6: =#REF! -> #REF! | S6: =#REF! -> #REF! | T6: =#REF! -> #REF! | U6: =A3 -> 0 | V6: =B3 -> Year
J7: RBI | K7: GDP | M7: Macro Data | R7: =#REF! -> #REF! | S7: =#REF! -> #REF! | T7: =#REF! -> #REF! | U7: =A8 -> 0 | V7: =B8 -> COST ASSUMPTIONS (% of Revenue)
B8: COST ASSUMPTIONS (% of Revenue) | J8: World Bank | K8: Macro | M8: Growth Rate By Country | S8: =S7-R7 -> #REF! | T8: =T7-S7 -> #REF! | U8: =U7-T7 -> #REF! | V8: =V7-U7 -> #VALUE!
B9: COGS % | C9: 0.55 | D9: 0.545 | E9: 0.54 | F9: 0.535 | G9: 0.53 | I9: Step 2 | J9: Historical Trend | T9: Negative trend is great
B10: Operating Expenses % | C10: 0.25 | D10: 0.245 | E10: 0.24 | F10: 0.235 | G10: 0.23 | J10: =#REF!&"-"&#REF! -> #REF! | K10: =#REF!&"-"&#REF! -> #REF! | L10: =A3&"-"&#REF! -> #REF! | M10: =B3&"-"&#REF! -> #REF! | Q10: Step 2 | R10: Decide Future Margin Behavior (THIS IS KEY)
B11: Depreciation % of Gross PPE | C11: 0.06 | D11: 0.06 | E11: 0.06 | F11: 0.06 | G11: 0.06 | J11: =#REF! -> #REF! | K11: =#REF! -> #REF! | L11: =A6 -> 0 | M11: =B6 -> Revenue Growth % | R11: Case Type | S11: Business Nature | T11: Typical Adjustment
K12: =K11-J11 -> #REF! | L12: =L11-K11 -> #REF! | M12: =M11-L11 -> #VALUE! | R12: Manufacturing | S12: Physical product | T12: Improve0.5–1%
B13: TAX ASSUMPTIONS | L13: Trend is Negative | R13: FMCG / Retail | S13: Consumer goods | T13: ±0.2–0.5% tweak
B14: Tax Rate % | C14: 0.25 | D14: 0.25 | E14: 0.25 | F14: 0.25 | G14: 0.25 | I14: Step 3 | J14: Forecast Rule | R14: SaaS / IT Services | S14: Software / digital | T14: Improve 0.3–0.7%
J15: Long-term growth id Lower than Industry CAGR | R15: Infrastructure | S15: Asset-heavy utilities | T15: Fuel inflation linked
B16: WORKING CAPITAL ASSUMPTIONS | R16: Commodity Business | S16: Raw material driven | T16: Link to price index
B17: Days Sales Outstanding (DSO) | C17: 45 | D17: 44 | E17: 43 | F17: 42 | G17: 41
B18: Days Inventory Outstanding (DIO) | C18: 60 | D18: 58 | E18: 56 | F18: 55 | G18: 54 | Q18: Step 3 | R18: Inflation Adjustment
B19: Days Payable Outstanding (DPO) | C19: 35 | D19: 36 | E19: 37 | F19: 38 | G19: 39 | R19: Apply raw material inflation
B21: CAPEX ASSUMPTIONS
B22: Capex % of Revenue | C22: 0.06 | D22: 0.055 | E22: 0.05 | F22: 0.045 | G22: 0.045
B24: DEBT ASSUMPTIONS
B25: Interest Rate on ST Debt % | C25: 0.045 | D25: 0.045 | E25: 0.045 | F25: 0.045 | G25: 0.045
B26: Interest Rate on LT Debt % | C26: 0.06 | D26: 0.06 | E26: 0.06 | F26: 0.06 | G26: 0.06
B27: New Debt Issuance | C27: 0 | D27: 0 | E27: 0 | F27: 0 | G27: 0
B28: Debt Repayment (% of CFO) | C28: 0.1 | D28: 0.1 | E28: 0.1 | F28: 0.1 | G28: 0.1
B30: DIVIDEND ASSUMPTIONS
B31: Dividend Payout Ratio % | C31: 0.2 | D31: 0.2 | E31: 0.2 | F31: 0.2 | G31: 0.2

Sheet Debt Schedule
B1: Debt Schedule
B3: Year | C3: 2024E | D3: 2025F | E3: 2026F | F3: 2027F | G3: 2028F | H3: 2029F
B5: SHORT-TERM DEBT
B6: Beginning Balance | C6: 8000 | D6: ='Balance Sheet'!C30 -> 8000 | E6: ='Balance Sheet'!D30 -> 8000 | F6: ='Balance Sheet'!E30 -> 8000 | G6: ='Balance Sheet'!F30 -> 8000 | H6: ='Balance Sheet'!G30 -> 8000
B7: New Debt Issued | C7: =Assumptions!C27 -> 0 | D7: =-'Cash Flow'!D19*Assumptions!D28 -> 0 | E7: =-'Cash Flow'!E19*Assumptions!E28 -> 0 | F7: =-'Cash Flow'!F19*Assumptions!F28 -> 0 | G7: =-'Cash Flow'!G19*Assumptions!G28 -> 0 | H7: =-'Cash Flow'!H19*Assumptions!H28 -> 0
B8: Debt Repayment | C8: 0 | D8: =Assumptions!C28*'Cash Flow'!D12 -> 0 | E8: =Assumptions!D28*'Cash Flow'!E12 -> 0 | F8: =Assumptions!E28*'Cash Flow'!F12 -> 0 | G8: =Assumptions!F28*'Cash Flow'!G12 -> 0 | H8: =Assumptions!G28*'Cash Flow'!H12 -> 0
B9: Ending Balance | C9: =C6+C7-C8 -> 8000 | D9: =D6+D7-D8 -> 8000 | E9: =E6+E7-E8 -> 8000 | F9: =F6+F7-F8 -> 8000 | G9: =G6+G7-G8 -> 8000 | H9: =H6+H7-H8 -> 8000
B10: Average Balance | C10: =(C6+C9)/2 -> 8000 | D10: =(D9+D6)/2 -> 8000 | E10: =(E9+E6)/2 -> 8000 | F10: =(F9+F6)/2 -> 8000 | G10: =(G9+G6)/2 -> 8000 | H10: =(H9+H6)/2 -> 8000
B11: Interest Rate | C11: 0.045 | D11: =Assumptions!C25 -> 0.045 | E11: =Assumptions!D25 -> 0.045 | F11: =Assumptions!E25 -> 0.045 | G11: =Assumptions!F25 -> 0.045 | H11: =Assumptions!G25 -> 0.045
B12: Interest Expense | C12: =C10*C11 -> 360 | D12: =D10*D11 -> 360 | E12: =E10*E11 -> 360 | F12: =F10*F11 -> 360 | G12: =G10*G11 -> 360 | H12: =H10*H11 -> 360
B15: LONG-TERM DEBT
B16: Beginning Balance | C16: 35000 | D16: =C19 -> 35000 | E16: =D19 -> 35000 | F16: =E19 -> 35000 | G16: =F19 -> 35000 | H16: =G19 -> 35000
B17: New Debt Issued | C17: 0 | D17: 0 | E17: 0 | F17: 0 | G17: 0 | H17: 0
B18: Debt Repayment | C18: 0 | D18: =Assumptions!C28*'Cash Flow'!D12 -> 0 | E18: =Assumptions!D28*'Cash Flow'!E12 -> 0 | F18: =Assumptions!E28*'Cash Flow'!F12 -> 0 | G18: =Assumptions!F28*'Cash Flow'!G12 -> 0 | H18: =Assumptions!G28*'Cash Flow'!H12 -> 0
B19: Ending Balance | C19: =C16+C17-C18 -> 35000 | D19: =D16+D17-D18 -> 35000 | E19: =E16+E17-E18 -> 35000 | F19: =F16+F17-F18 -> 35000 | G19: =G16+G17-G18 -> 35000 | H19: =H16+H17-H18 -> 35000
B20: Average Balance | C20: =(C16+C19)/2 -> 35000 | D20: =(D16+D19)/2 -> 35000 | E20: =(E16+E19)/2 -> 35000 | F20: =(F16+F19)/2 -> 35000 | G20: =(G16+G19)/2 -> 35000 | H20: =(H16+H19)/2 -> 35000
B21: Interest Rate | C21: 0.06 | D21: =Assumptions!C26 -> 0.06 | E21: =Assumptions!D26 -> 0.06 | F21: =Assumptions!E26 -> 0.06 | G21: =Assumptions!F26 -> 0.06 | H21: =Assumptions!G26 -> 0.06
B22: Interest Expense | C22: =C20*C21 -> 2100 | D22: =D20*D21 -> 2100 | E22: =E20*E21 -> 2100 | F22: =F20*F21 -> 2100 | G22: =G20*G21 -> 2100 | H22: =H20*H21 -> 2100
B25: TOTAL INTEREST EXPENSE | C25: =C12+C22 -> 2460 | D25: =D12+D22 -> 2460 | E25: =E12+E22 -> 2460 | F25: =F12+F22 -> 2460 | G25: =G12+G22 -> 2460 | H25: =H12+H22 -> 2460

Sheet PPE Schedule
B1: ASSUMPTIONS
B3: Year | C3: 2024E | D3: 2025F | E3: 2026F | F3: 2027F | G3: 2028F | H3: 2029F
B5: GROSS PPE
B6: Beginning Balance | C6: 80000 | D6: ='Balance Sheet'!C15 -> 80000 | E6: =D9 -> 74060 | F6: =E9 -> 68120 | G6: =F9 -> 62292.86 | H6: =G9 -> 56028.685
A7: + | B7: Capital Expenditures | D7: =-'Income Statement'!D5*Assumptions!D22 -> -5940 | E7: =-'Income Statement'!E5*Assumptions!E22 -> -5940 | F7: =-'Income Statement'!F5*Assumptions!F22 -> -5827.14 | G7: =-'Income Statement'!G5*Assumptions!G22 -> -6264.1755 | H7: =-'Income Statement'!H5*Assumptions!H22 -> 0
A8: - | B8: Asset Disposals | C8: 0 | D8: 0 | E8: 0 | F8: 0 | G8: 0
B9: Ending Balance | C9: =C6+C7-C8 -> 80000 | D9: =D6+D7-D8 -> 74060 | E9: =E6+E7-E8 -> 68120 | F9: =F6+F7-F8 -> 62292.86 | G9: =G6+G7-G8 -> 56028.685 | H9: =H6+H7-H8 -> 56028.685
B12: ACCUMULATED DEPRECIATION
B13: Beginning Balance | C13: 32000 | D13: ='Balance Sheet'!C16 -> 32000 | E13: ='Balance Sheet'!D16 -> 36800 | F13: ='Balance Sheet'!E16 -> 41243.6 | G13: ='Balance Sheet'!F16 -> 45330.8 | H13: ='Balance Sheet'!G16 -> 49068.372
B14: Depreciation Expense | D14: =D6*Assumptions!C11 -> 4800 | E14: =E6*Assumptions!D11 -> 4443.6 | F14: =F6*Assumptions!E11 -> 4087.2 | G14: =G6*Assumptions!F11 -> 3737.5716 | H14: =H6*Assumptions!G11 -> 3361.7211
B15: Ending Balance | C15: =C13-C14 -> 32000 | D15: =D13+D14 -> 36800 | E15: =E13+E14 -> 41243.6 | F15: =F13+F14 -> 45330.8 | G15: =G13+G14 -> 49068.372 | H15: =H13+H14 -> 52430.093
B17: Net PPE | C17: =C9-C15 -> 48000 | D17: =D9-D15 -> 37260 | E17: =E9-E15 -> 26876.4 | F17: =F9-F15 -> 16962.06 | G17: =G9-G15 -> 6960.3129 | H17: =H9-H15 -> 3598.5918

Sheet NWC Schedule
B1: NET WORKING CAPITAL SCHEDULE
B3: Year | C3: 2024E | D3: 2025F | E3: 2026F | F3: 2027F | G3: 2028F | H3: 2029F
B5: Revenue | D5: ='Income Statement'!D5 -> 108000 | E5: ='Income Statement'!E5 -> 118800 | F5: ='Income Statement'!F5 -> 129492 | G5: ='Income Statement'!G5 -> 139203.9 | H5: ='Income Statement'!H5 -> 148252.15
B6: COGS | D6: ='Income Statement'!D8 -> 59400 | E6: ='Income Statement'!E8 -> 64746 | F6: ='Income Statement'!F8 -> 69925.68 | G6: ='Income Statement'!G8 -> 74474.087 | H6: ='Income Statement'!H8 -> 78573.641
B9: ACCOUNTS RECEIVABLE
B10: Days Sales Outstanding (DSO) | D10: =Assumptions!C17 -> 45 | E10: =Assumptions!D17 -> 44 | F10: =Assumptions!E17 -> 43 | G10: =Assumptions!F17 -> 42 | H10: =Assumptions!G17 -> 41
B11: Accounts Receivable | D11: =(D5/365)*D10 -> 13315.068 | E11: =(E5/365)*E10 -> 14321.096 | F11: =(F5/365)*F10 -> 15255.222 | G11: =(G5/365)*G10 -> 16017.983 | H11: =(H5/365)*H10 -> 16652.982
B13: INVENTORY
B14: Days Inventory Outstanding (DIO) | D14: =Assumptions!C18 -> 60 | E14: =Assumptions!D18 -> 58 | F14: =Assumptions!E18 -> 56 | G14: =Assumptions!F18 -> 55 | H14: =Assumptions!G18 -> 54
B15: Inventory | D15: =(D14/365)*D6 -> 9764.3836 | E15: =(E14/365)*E6 -> 10288.405 | F15: =(F14/365)*F6 -> 10728.324 | G15: =(G14/365)*G6 -> 11222.123 | H15: =(H14/365)*H6 -> 11624.594
B17: ACCOUNTS PAYABLE
B18: Days Payable Outstanding (DPO) | D18: =Assumptions!C19 -> 35 | E18: =Assumptions!D19 -> 36 | F18: =Assumptions!E19 -> 37 | G18: =Assumptions!F19 -> 38 | H18: =Assumptions!G19 -> 39
B19: Accounts Payable | D19: =(D18/365)*D6 -> 5695.8904 | E19: =(E18/365)*E6 -> 6385.9068 | F19: =(F18/365)*F6 -> 7088.3566 | G19: =(G18/365)*G6 -> 7753.4665 | H19: =(H18/365)*H6 -> 8395.5398
B22: NET WORKING CAPITAL
B23: Accounts Receivable | D23: =D11 -> 13315.068 | E23: =E11 -> 14321.096 | F23: =F11 -> 15255.222 | G23: =G11 -> 16017.983 | H23: =H11 -> 16652.982
B24: Inventory | D24: =D15 -> 9764.3836 | E24: =E15 -> 10288.405 | F24: =F15 -> 10728.324 | G24: =G15 -> 11222.123 | H24: =H15 -> 11624.594
B25: Accounts Payable | D25: =D19 -> 5695.8904 | E25: =E19 -> 6385.9068 | F25: =F19 -> 7088.3566 | G25: =G19 -> 7753.4665 | H25: =H19 -> 8395.5398
B26: Total NWC | C26: 20000 | D26: =D23+D24-D25 -> 17383.562 | E26: =E23+E24-E25 -> 18223.595 | F26: =F23+F24-F25 -> 18895.189 | G26: =G23+G24-G25 -> 19486.639 | H26: =H23+H24-H25 -> 19882.035
B28: Change in NWC (Δ NWC) | D28: =D26-C26 -> -2616.4384 | E28: =E26-D26 -> 840.03288 | F28: =F26-E26 -> 671.5943 | G28: =G26-F26 -> 591.45028 | H28: =H26-G26 -> 395.39628

Sheet Income Statement
B1: INCOME STATEMENT | D1: All figures in thousands
B3: Year | C3: 2024E | D3: 2025F | E3: 2026F | F3: 2027F | G3: 2028F | H3: 2029F
B5: Revenue | C5: 100000 | D5: =C5*(1+Assumptions!C6) -> 108000 | E5: =D5*(1+Assumptions!D6) -> 118800 | F5: =E5*(1+Assumptions!E6) -> 129492 | G5: =F5*(1+Assumptions!F6) -> 139203.9 | H5: =G5*(1+Assumptions!G6) -> 148252.15
B6: % Change | D6: =D5/C5-1 -> 0.08 | E6: =E5/D5-1 -> 0.1 | F6: =F5/E5-1 -> 0.09 | G6: =G5/F5-1 -> 0.075 | H6: =H5/G5-1 -> 0.065
B8: Cost of Goods Sold | C8: 55000 | D8: =D5*D9 -> 59400 | E8: =E5*E9 -> 64746 | F8: =F5*F9 -> 69925.68 | G8: =G5*G9 -> 74474.087 | H8: =H5*H9 -> 78573.641 | I8: =H5*Assumptions!H9 -> 0
B9: % of Revenue | D9: =Assumptions!C9 -> 0.55 | E9: =Assumptions!D9 -> 0.545 | F9: =Assumptions!E9 -> 0.54 | G9: =Assumptions!F9 -> 0.535 | H9: =Assumptions!G9 -> 0.53
B11: Gross Profit | C11: =C5-C8 -> 45000 | D11: =D5-D8 -> 48600 | E11: =E5-E8 -> 54054 | F11: =F5-F8 -> 59566.32 | G11: =G5-G8 -> 64729.814 | H11: =H5-H8 -> 69678.512
B12: Gross Margin % | D12: =D11/D5 -> 0.45 | E12: =E11/E5 -> 0.455 | F12: =F11/F5 -> 0.46 | G12: =G11/G5 -> 0.465 | H12: =H11/H5 -> 0.47
B14: Operating Expenses | C14: 25000 | D14: =D5*D15 -> 27000 | E14: =E5*E15 -> 29106 | F14: =F5*F15 -> 31078.08 | G14: =G5*G15 -> 32712.917 | H14: =H5*H15 -> 34097.995
B15: % of Revenue | D15: =Assumptions!C10 -> 0.25 | E15: =Assumptions!D10 -> 0.245 | F15: =Assumptions!E10 -> 0.24 | G15: =Assumptions!F10 -> 0.235 | H15: =Assumptions!G10 -> 0.23
B17: EBITDA | D17: =D11-D14 -> 21600 | E17: =E11-E14 -> 24948 | F17: =F11-F14 -> 28488.24 | G17: =G11-G14 -> 32016.897 | H17: =H11-H14 -> 35580.517
B18: Depreciation & Amortization | D18: ='PPE Schedule'!D14 -> 4800 | E18: ='PPE Schedule'!E14 -> 4443.6 | F18: ='PPE Schedule'!F14 -> 4087.2 | G18: ='PPE Schedule'!G14 -> 3737.5716 | H18: ='PPE Schedule'!H14 -> 3361.7211
B20: EBIT | D20: =D17-D18 -> 16800 | E20: =E17-E18 -> 20504.4 | F20: =F17-F18 -> 24401.04 | G20: =G17-G18 -> 28279.325 | H20: =H17-H18 -> 32218.796
B21: EBIT Margin % | D21: =D20/D5 -> 0.15555556 | E21: =E20/E5 -> 0.17259596 | F21: =F20/F5 -> 0.18843666 | G21: =G20/G5 -> 0.20315038 | H21: =H20/H5 -> 0.2173243
B23: Interest Expense | D23: ='Debt Schedule'!D25 -> 2460 | E23: ='Debt Schedule'!E25 -> 2460 | F23: ='Debt Schedule'!F25 -> 2460 | G23: ='Debt Schedule'!G25 -> 2460 | H23: ='Debt Schedule'!H25 -> 2460
B25: Earnings Before Tax (EBT) | D25: =D20-D23 -> 14340 | E25: =E20-E23 -> 18044.4 | F25: =F20-F23 -> 21941.04 | G25: =G20-G23 -> 25819.325 | H25: =H20-H23 -> 29758.796
B27: Tax Expense | D27: =D25*D28 -> 3585 | E27: =E25*E28 -> 4511.1 | F27: =F25*F28 -> 5485.26 | G27: =G25*G28 -> 6454.8314 | H27: =H25*H28 -> 7439.6989
D28: =Assumptions!C14 -> 0.25 | E28: =Assumptions!D14 -> 0.25 | F28: =Assumptions!E14 -> 0.25 | G28: =Assumptions!F14 -> 0.25 | H28: =Assumptions!G14 -> 0.25
B30: NET INCOME | D30: =D25-D27 -> 10755 | E30: =E25-E27 -> 13533.3 | F30: =F25-F27 -> 16455.78 | G30: =G25-G27 -> 19364.494 | H30: =H25-H27 -> 22319.097
B31: NI Margin % | D31: =D30/D5 -> 0.099583333 | E31: =E30/E5 -> 0.11391667 | F31: =F30/F5 -> 0.12707951 | G31: =G30/G5 -> 0.13910885 | H31: =H30/H5 -> 0.15054821
B33: Dividend | D33: =D30*D34 -> 2151 | E33: =E30*E34 -> 2706.66 | F33: =F30*F34 -> 3291.156 | G33: =G30*G34 -> 3872.8988 | H33: =H30*H34 -> 4463.8194
B34: Dividend Payout Ratio % | D34: =Assumptions!C31 -> 0.2 | E34: =Assumptions!D31 -> 0.2 | F34: =Assumptions!E31 -> 0.2 | G34: =Assumptions!F31 -> 0.2 | H34: =Assumptions!G31 -> 0.2
B36: Retained Earnings | D36: =D30*(1-D34) -> 8604 | E36: =E30*(1-E34) -> 10826.64 | F36: =F30*(1-F34) -> 13164.624 | G36: =G30*(1-G34) -> 15491.595 | H36: =H30*(1-H34) -> 17855.277

Sheet Cash Flow
B1: CASH FLOW STATEMENT | H1: All figures in thousands
B3: Year | D3: 2025F | E3: 2026F | F3: 2027F | G3: 2028F | H3: 2029F
B5: CASH FLOW FROM OPERATIONS
A6: × | B6: Net Income | D6: ='Income Statement'!D30 -> 10755 | E6: ='Income Statement'!E30 -> 13533.3 | F6: ='Income Statement'!F30 -> 16455.78 | G6: ='Income Statement'!G30 -> 19364.494 | H6: ='Income Statement'!H30 -> 22319.097
A7: × | B7: Depreciation & Amortization | D7: ='Income Statement'!D18 -> 4800 | E7: ='Income Statement'!E18 -> 4443.6 | F7: ='Income Statement'!F18 -> 4087.2 | G7: ='Income Statement'!G18 -> 3737.5716 | H7: ='Income Statement'!H18 -> 3361.7211
B8: Change in Accounts Receivable | D8: =-('NWC Schedule'!D11-'NWC Schedule'!C11) -> -13315.068 | E8: =-('NWC Schedule'!E11-'NWC Schedule'!D11) -> -1006.0274 | F8: =-('NWC Schedule'!F11-'NWC Schedule'!E11) -> -934.12603 | G8: =-('NWC Schedule'!G11-'NWC Schedule'!F11) -> -762.7611 | H8: =-('NWC Schedule'!H11-'NWC Schedule'!G11) -> -634.99861
B9: Change in Inventory | D9: =-('NWC Schedule'!D14-'NWC Schedule'!C14) -> -60 | E9: =-('NWC Schedule'!E14-'NWC Schedule'!D14) -> 2 | F9: =-('NWC Schedule'!F14-'NWC Schedule'!E14) -> 2 | G9: =-('NWC Schedule'!G14-'NWC Schedule'!F14) -> 1 | H9: =-('NWC Schedule'!H14-'NWC Schedule'!G14) -> 1
B10: Change in Accounts Payable | D10: ='NWC Schedule'!D17-'NWC Schedule'!C17 -> 0 | E10: ='NWC Schedule'!E17-'NWC Schedule'!D17 -> 0 | F10: ='NWC Schedule'!F17-'NWC Schedule'!E17 -> 0 | G10: ='NWC Schedule'!G17-'NWC Schedule'!F17 -> 0 | H10: ='NWC Schedule'!H17-'NWC Schedule'!G17 -> 0
B11: Change in Other Working Capital | C11: 0 | E11: 0 | F11: 0 | G11: 0 | H11: 0
B12: Cash Flow from Operations | C12: =C6+C7+C8+C9+C10+C11 -> 0
B15: CASH FLOW FROM INVESTING | D15: ='PPE Schedule'!D7 -> -5940 | E15: ='PPE Schedule'!E7 -> -5940 | F15: ='PPE Schedule'!F7 -> -5827.14 | G15: ='PPE Schedule'!G7 -> -6264.1755 | H15: ='PPE Schedule'!H7 -> 0
B16: Capital Expenditures | E16: 0 | F16: 0 | G16: 0 | H16: 0
B17: Asset Sales / Proceeds | C17: 0 | E17: 0 | F17: 0 | G17: 0 | H17: 0
B18: Investments Purchased | C18: 0
B19: Cash Flow from Investing | C19: =C16+C17+C18 -> 0
D21: ='Debt Schedule'!D5+'Debt Schedule'!#REF! -> #REF! | E21: ='Debt Schedule'!E5+'Debt Schedule'!#REF! -> #REF! | F21: ='Debt Schedule'!F5+'Debt Schedule'!#REF! -> #REF! | G21: ='Debt Schedule'!G5+'Debt Schedule'!#REF! -> #REF! | H21: ='Debt Schedule'!H5+'Debt Schedule'!#REF! -> #REF!
B22: CASH FLOW FROM FINANCING | D22: =-'Debt Schedule'!D7-'Debt Schedule'!D18 -> 0 | E22: =-'Debt Schedule'!E7-'Debt Schedule'!E18 -> 0 | F22: =-'Debt Schedule'!F7-'Debt Schedule'!F18 -> 0 | G22: =-'Debt Schedule'!G7-'Debt Schedule'!G18 -> 0 | H22: =-'Debt Schedule'!H7-'Debt Schedule'!H18 -> 0
B23: New Debt Issued | E23: 0 | F23: 0 | G23: 0 | H23: 0
B24: Debt Repayment | D24: =-'Income Statement'!#REF!*Assumptions!D31 -> #REF! | E24: =-'Income Statement'!#REF!*Assumptions!E31 -> #REF! | F24: =-'Income Statement'!#REF!*Assumptions!F31 -> #REF! | G24: =-'Income Statement'!#REF!*Assumptions!G31 -> #REF! | H24: =-'Income Statement'!#REF!*Assumptions!H31 -> #REF!
B25: Equity Issued | C25: 0
B26: Dividends Paid | D26: ='Income Statement'!D33 -> 2151 | E26: ='Income Statement'!E33 -> 2706.66 | F26: ='Income Statement'!F33 -> 3291.156 | G26: ='Income Statement'!G33 -> 3872.8988 | H26: ='Income Statement'!H33 -> 4463.8194
B27: Cash Flow from Financing | C27: =C23+C24+C25+C26 -> 0
D29: ='Balance Sheet'!C6 -> 0 | E29: ='Balance Sheet'!D6 -> 0 | F29: ='Balance Sheet'!E6 -> 0 | G29: ='Balance Sheet'!F6 -> 0 | H29: ='Balance Sheet'!G6 -> 0
B30: NET CHANGE IN CASH | C30: =C12+C19+C27 -> 0
B32: Beginning Cash
B33: Ending Cash | C33: =C32+C30 -> 0

Sheet Balance Sheet
B1: BALANCE SHEET | C1: All figures in thousands
B3: Year | C3: 2024E | D3: 2025F | E3: 2026F | F3: 2027F | G3: 2028F | H3: 2029F
B5: ASSETS
B6: Current Assets
B7: Cash & Cash Equivalents | C7: 15000
A8: × | B8: Accounts Receivable | C8: 12000 | D8: ='NWC Schedule'!D23 -> 13315.068 | E8: ='NWC Schedule'!E23 -> 14321.096 | F8: ='NWC Schedule'!F23 -> 15255.222 | G8: ='NWC Schedule'!G23 -> 16017.983 | H8: ='NWC Schedule'!H23 -> 16652.982
A9: × | B9: Inventory | C9: 18000 | D9: ='NWC Schedule'!D15 -> 9764.3836 | E9: ='NWC Schedule'!E15 -> 10288.405 | F9: ='NWC Schedule'!F15 -> 10728.324 | G9: ='NWC Schedule'!G15 -> 11222.123 | H9: ='NWC Schedule'!H15 -> 11624.594
B10: Loans & Advances | C10: 3000 | D10: =C10 -> 3000 | E10: =D10 -> 3000 | F10: =E10 -> 3000 | G10: =F10 -> 3000 | H10: =G10 -> 3000
B11: Other Current Assets | C11: 2000
B12: ` | C12: =SUM(C7:C11) -> 50000
B14: Non-Current Assets
A15: × | B15: Property, Plant & Equipment (Gross) | C15: 80000 | D15: ='PPE Schedule'!D9 -> 74060 | E15: ='PPE Schedule'!E9 -> 68120 | F15: ='PPE Schedule'!F9 -> 62292.86 | G15: ='PPE Schedule'!G9 -> 56028.685 | H15: ='PPE Schedule'!H9 -> 56028.685
A16: × | B16: Less: Accumulated Depreciation | C16: 32000 | D16: ='PPE Schedule'!D15 -> 36800 | E16: ='PPE Schedule'!E15 -> 41243.6 | F16: ='PPE Schedule'!F15 -> 45330.8 | G16: ='PPE Schedule'!G15 -> 49068.372 | H16: ='PPE Schedule'!H15 -> 52430.093
A17: × | B17: Net PPE | C17: =C15-C16 -> 48000 | D17: =D15-D16 -> 37260 | E17: =E15-E16 -> 26876.4 | F17: =F15-F16 -> 16962.06 | G17: =G15-G16 -> 6960.3129 | H17: =H15-H16 -> 3598.5918
B18: Capital Work in Progress (CWIP) | C18: 5000 | D18: =C18 -> 5000 | E18: =D18 -> 5000 | F18: =E18 -> 5000 | G18: =F18 -> 5000 | H18: =G18 -> 5000
B19: Other Fixed Assets | C19: 3000 | D19: =C19 -> 3000 | E19: =D19 -> 3000 | F19: =E19 -> 3000 | G19: =F19 -> 3000 | H19: =G19 -> 3000
B20: Investments | C20: 8000
B21: Deferred Tax Asset | C21: 1500
B22: Total Non-Current Assets | C22: =C17+SUM(C18:C21) -> 65500
B24: TOTAL ASSETS | C24: =C12+C22 -> 115500 | D24: =D12+D22 -> 0 | E24: =E12+E22 -> 0 | F24: =F12+F22 -> 0 | G24: =G12+G22 -> 0 | H24: =H12+H22 -> 0
B27: LIABILITIES & EQUITY
B28: Current Liabilities
A29: × | B29: Accounts Payable | C29: 10000 | D29: ='NWC Schedule'!D25 -> 5695.8904 | E29: ='NWC Schedule'!E25 -> 6385.9068 | F29: ='NWC Schedule'!F25 -> 7088.3566 | G29: ='NWC Schedule'!G25 -> 7753.4665 | H29: ='NWC Schedule'!H25 -> 8395.5398
B30: Short-Term Debt | C30: ='Debt Schedule'!C9 -> 8000 | D30: ='Debt Schedule'!D9 -> 8000 | E30: ='Debt Schedule'!E9 -> 8000 | F30: ='Debt Schedule'!F9 -> 8000 | G30: ='Debt Schedule'!G9 -> 8000 | H30: ='Debt Schedule'!H9 -> 8000
B31: Accrued Expenses | C31: 4000 | D31: =C31 -> 4000 | E31: =D31 -> 4000 | F31: =E31 -> 4000 | G31: =F31 -> 4000 | H31: =G31 -> 4000
B32: Taxes Payable | C32: 2500 | D32: =C32 -> 2500 | E32: =D32 -> 2500 | F32: =E32 -> 2500 | G32: =F32 -> 2500 | H32: =G32 -> 2500
B33: Unearned Revenue | C33: 1500 | D33: =C33 -> 1500 | E33: =D33 -> 1500 | F33: =E33 -> 1500 | G33: =F33 -> 1500 | H33: =G33 -> 1500
B34: Other Borrowings | C34: 2000 | D34: =C34 -> 2000 | E34: =D34 -> 2000 | F34: =E34 -> 2000 | G34: =F34 -> 2000 | H34: =G34 -> 2000
B35: Other Current Liabilities | C35: 1000
B36: Total Current Liabilities | C36: =SUM(C29:C35) -> 29000
B38: Non-Current Liabilities
B39: Long-Term Debt | C39: ='Debt Schedule'!C19 -> 35000 | D39: ='Debt Schedule'!D19 -> 35000 | E39: ='Debt Schedule'!E19 -> 35000 | F39: ='Debt Schedule'!F19 -> 35000 | G39: ='Debt Schedule'!G19 -> 35000 | H39: ='Debt Schedule'!H19 -> 35000
B40: Lease Liabilities | C40: 4000 | D40: =C40 -> 4000 | E40: =D40 -> 4000 | F40: =E40 -> 4000 | G40: =F40 -> 4000 | H40: =G40 -> 4000
B41: Deferred Tax Liability | C41: 3000
B42: Provisions | C42: 2000
B43: Total Non-Current Liabilities | C43: =SUM(C39:C42) -> 44000
B45: TOTAL LIABILITIES | C45: =C36+C43 -> 73000 | D45: =D36+D43 -> 0 | E45: =E36+E43 -> 0 | F45: =F36+F43 -> 0 | G45: =G36+G43 -> 0 | H45: =H36+H43 -> 0
D47: =C47 -> 0 | E47: =D47 -> 0 | F47: =E47 -> 0 | G47: =F47 -> 0 | H47: =G47 -> 0
B48: Shareholder's Equity | D48: =C48 -> 0 | E48: =D48 -> 0 | F48: =E48 -> 0 | G48: =F48 -> 0 | H48: =G48 -> 0
B49: Equity Share Capital | C49: 10000 | D49: =C49+'Income Statement'!#REF!+'Cash Flow'!D24 -> #REF! | E49: =D49+'Income Statement'!#REF!+'Cash Flow'!E24 -> #REF! | F49: =E49+'Income Statement'!#REF!+'Cash Flow'!F24 -> #REF! | G49: =F49+'Income Statement'!#REF!+'Cash Flow'!G24 -> #REF! | H49: =G49+'Income Statement'!#REF!+'Cash Flow'!H24 -> #REF!
...

Sheet Ratio Analysis
B1: Ratio Analysis
E2: Historical Result | J2: Forecast Period
E3: 2021 | F3: 2022 | G3: 2023 | H3: 2024 | I3: 2025 | J3: 2026 | K3: 2027 | L3: 2028 | M3: 2029 | N3: 2030
B6: PROFITABILITY | D6: Industry Avg.
B7: Gross Margin | C7: Pricing power + cost efficiency | E7: =[1]IS!F9/[1]IS!F5 -> 0.21859395 | F7: =[1]IS!G9/[1]IS!G5 -> 0.18373268 | G7: =[1]IS!H9/[1]IS!H5 -> 0.15292683 | H7: =[1]IS!I9/[1]IS!I5 -> 0.13314815 | I7: =[1]IS!J9/[1]IS!J5 -> 0.17057216 | J7: =[1]IS!K9/[1]IS!K5 -> 0.17179475 | K7: =[1]IS!L9/[1]IS!L5 -> 0.16243492 | L7: =[1]IS!M9/[1]IS!M5 -> 0.15817536 | ... N7: =[1]IS!O9/[1]IS!O5 -> 0.16444045
B8: EBITDA Margin | C8: Core operating profitability | E8: =[1]IS!F12/[1]IS!F5 -> 0.11203858 | F8: =[1]IS!G12/[1]IS!G5 -> 0.093036316 | G8: =[1]IS!H12/[1]IS!H5 -> 0.079268293 | H8: =[1]IS!I12/[1]IS!I5 -> 0.067901235 | I8: =[1]IS!J12/[1]IS!J5 -> 0.088540834 | J8: =[1]IS!K12/[1]IS!K5 -> 0.088157052 | K8: =[1]IS!L12/[1]IS!L5 -> 0.083380746 | L8: =[1]IS!M12/[1]IS!M5 -> 0.081449632 | ... N8: =[1]IS!O12/[1]IS!O5 -> 0.084682833
B9: EBIT Margin | C9: Operating efficiency after depreciation | E9: =[1]IS!F15/[1]IS!F5 -> 0.096642552 | F9: =[1]IS!G15/[1]IS!G5 -> 0.075814302 | G9: =[1]IS!H15/[1]IS!H5 -> 0.066395664 | H9: =[1]IS!I15/[1]IS!I5 -> 0.057581019 | I9: =[1]IS!J15/[1]IS!J5 -> 0.080549784 | J9: =[1]IS!K15/[1]IS!K5 -> 0.088157052 | K9: =[1]IS!L15/[1]IS!L5 -> 0.083380746 | L9: =[1]IS!M15/[1]IS!M5 -> 0.081449632 | ... N9: =[1]IS!O15/[1]IS!O5 -> 0.084682833
B10: Net Profit Margin | C10: Final profit retained | E10: =[1]IS!F21/[1]IS!F5 -> 0.065843072 | F10: =[1]IS!G21/[1]IS!G5 -> 0.051486335 | G10: =[1]IS!H21/[1]IS!H5 -> 0.041756098 | H10: =[1]IS!I21/[1]IS!I5 -> 0.033194444 | I10: =[1]IS!J21/[1]IS!J5 -> 0.049423046 | J10: =[1]IS!K21/[1]IS!K5 -> 0.063473077 | K10: =[1]IS!L21/[1]IS!L5 -> 0.060034137 | L10: =[1]IS!M21/[1]IS!M5 -> 0.058643735 | ... N10: =[1]IS!O21/[1]IS!O5 -> 0.06097164
B11: ROE | C11: Return to shareholders | E11: =[1]IS!F21/[1]BS!F50 -> 0.074603401 | F11: =[1]IS!G21/(([1]BS!F50+[1]BS!G50)/2) -> 0.056715125 | G11: =[1]IS!H21/(([1]BS!G50+[1]BS!H50)/2) -> 0.05892048 | H11: =[1]IS!I21/(([1]BS!H50+[1]BS!I50)/2) -> 0.058658704 | I11: =[1]IS!J21/(([1]BS!I50+[1]BS!J50)/2) -> 0.093996492 | J11: =[1]IS!K21/(([1]BS!J50+[1]BS!K50)/2) -> 0.2494898 | K11: =[1]IS!L21/(([1]BS!K50+[1]BS!L50)/2) -> 1.0739203 | L11: =[1]IS!M21/(([1]BS!L50+[1]BS!M50)/2) -> 1.0817839 | M11: =[1]IS!N21/(([1]BS!M50+[1]BS!N50)/2) -> 1.0877669 | N11: =[1]IS!O21/(([1]BS!N50+[1]BS!O50)/2) -> 1.0933398
B12: ROA | C12: Asset utilization efficiency | E12: =[1]IS!F21/(([1]BS!F22)) -> #REF! | F12: =[1]IS!G21/(([1]BS!F22+[1]BS!G22)/2) -> #REF! | G12: =[1]IS!H21/(([1]BS!G22+[1]BS!H22)/2) -> #REF! | H12: =[1]IS!I21/(([1]BS!H22+[1]BS!I22)/2) -> #REF! | I12: =[1]IS!J21/(([1]BS!I22+[1]BS!J22)/2) -> #REF! | J12: =[1]IS!K21/(([1]BS!J22+[1]BS!K22)/2) -> #REF! | K12: =[1]IS!L21/(([1]BS!K22+[1]BS!L22)/2) -> #DIV/0! | L12: =[1]IS!M21/(([1]BS!L22+[1]BS!M22)/2) -> #DIV/0! | M12: =[1]IS!N21/(([1]BS!M22+[1]BS!N22)/2) -> #DIV/0! | N12: =[1]IS!O21/(([1]BS!N22+[1]BS!O22)/2) -> #DIV/0!
B13: ROIC | C13: Capital efficiency | E13: =[1]IS!F15*(1-[1]IS!$F$20)/('[1]Supporting Schedules'!F14+'[1]Supporting Schedules'!F22) -> #REF! | F13: =[1]IS!G15*(1-[1]IS!$F$20)/('[1]Supporting Schedules'!G14+'[1]Supporting Schedules'!G22) -> #REF! | G13: =[1]IS!H15*(1-[1]IS!$F$20)/('[1]Supporting Schedules'!H14+'[1]Supporting Schedules'!H22) -> #REF! | H13: =[1]IS!I15*(1-[1]IS!$F$20)/('[1]Supporting Schedules'!I14+'[1]Supporting Schedules'!I22) -> #REF! | I13: =[1]IS!J15*(1-[1]IS!$F$20)/('[1]Supporting Schedules'!J14+'[1]Supporting Schedules'!J22) -> #REF! | J13: =[1]IS!K15*(1-[1]IS!$F$20)/('[1]Supporting Schedules'!K14+'[1]Supporting Schedules'!K22) -> #REF! | K13: =[1]IS!L15*(1-[1]IS!$F$20)/('[1]Supporting Schedules'!L14+'[1]Supporting Schedules'!L22) -> #REF! | L13: =[1]IS!M15*(1-[1]IS!$F$20)/('[1]Supporting Schedules'!M14+'[1]Supporting Schedules'!M22) -> #REF! | ... N13: =[1]IS!O15*(1-[1]IS!$F$20)/('[1]Supporting Schedules'!O14+'[1]Supporting Schedules'!O22) -> #REF!
B15: LIQUIDITY
B16: Current Ratio | C16: Short-term solvency
B17: Quick Ratio | C17: Liquidity without inventory
B18: Cash Ratio | C18: Pure cash safety
B19: Working Capital Ratio | C19: Operating liquidity intensity
B21: LEVERAGE
B22: Debt/Equity | C22: Capital structure risk
B23: Debt/EBITDA | C23: Debt repayment capacity
B24: Net Debt/EBITDA | C24: True leverage
B25: Interest Coverage | C25: Interest servicing ability
B26: Debt Ratio | C26: Balance sheet leverage
B28: EFFICIENCY
B29: Asset Turnover | C29: Asset productivity
B30: Fixed Asset Turnover | C30: Asset utilization
B31: Inventory Turnover | C31: Stock movement speed
B32: Receivable Turnover | C32: Collection efficiency
B34: WC
B35: DSO | C35: Collection days
B36: DIO | C36: Inventory holding period
B37: DPO | C37: Supplier credit period
B38: CCC | C38: Cash lock-up duration
B40: CASH FLOW
B41: Operating CF Margin | C41: Cash profitability
B42: FCF Margin | C42: Free cash strength
B43: Cash Conversion Ratio | C43: Earnings quality
B44: Capex Ratio | C44: Reinvestment intensity

Sheet Checks
A1: MODEL INTEGRITY CHECKS
A3: Check Type | B3: 2025F | C3: 2026F | D3: 2027F | E3: 2028F | F3: 2029F
A5: Balance Sheet Check (Assets = Liab + Equity) | B5: ='Balance Sheet'!D23-'Balance Sheet'!D52 -> 0 | C5: ='Balance Sheet'!E23-'Balance Sheet'!E52 -> 0 | D5: ='Balance Sheet'!F23-'Balance Sheet'!F52 -> 0 | E5: ='Balance Sheet'!G23-'Balance Sheet'!G52 -> 0 | F5: ='Balance Sheet'!H23-'Balance Sheet'!H52 -> 0
A6: Status | B6: =IF(ABS(B5)<0.01,"PASS","FAIL") -> PASS | C6: =IF(ABS(C5)<0.01,"PASS","FAIL") -> PASS | D6: =IF(ABS(D5)<0.01,"PASS","FAIL") -> PASS | E6: =IF(ABS(E5)<0.01,"PASS","FAIL") -> PASS | F6: =IF(ABS(F5)<0.01,"PASS","FAIL") -> PASS
A9: Cash Flow Check (BS Cash = CF Calc) | B9: ='Balance Sheet'!D6-'Cash Flow'!D30 -> 0 | C9: ='Balance Sheet'!E6-'Cash Flow'!E30 -> 0 | D9: ='Balance Sheet'!F6-'Cash Flow'!F30 -> 0 | E9: ='Balance Sheet'!G6-'Cash Flow'!G30 -> 0 | F9: ='Balance Sheet'!H6-'Cash Flow'!H30 -> 0
A10: Status | B10: =IF(ABS(B9)<0.01,"PASS","FAIL") -> PASS | C10: =IF(ABS(C9)<0.01,"PASS","FAIL") -> PASS | D10: =IF(ABS(D9)<0.01,"PASS","FAIL") -> PASS | E10: =IF(ABS(E9)<0.01,"PASS","FAIL") -> PASS | F10: =IF(ABS(F9)<0.01,"PASS","FAIL") -> PASS
A13: NWC Check (NWC = AR + Inv - AP) | B13: ='NWC Schedule'!D25-('NWC Schedule'!D11+'NWC Schedule'!D14-'NWC Schedule'!D17) -> -7679.1781 | C13: ='NWC Schedule'!E25-('NWC Schedule'!E11+'NWC Schedule'!E14-'NWC Schedule'!E17) -> -7993.189 | D13: ='NWC Schedule'!F25-('NWC Schedule'!F11+'NWC Schedule'!F14-'NWC Schedule'!F17) -> -8222.8653 | E13: ='NWC Schedule'!G25-('NWC Schedule'!G11+'NWC Schedule'!G14-'NWC Schedule'!G17) -> -8319.5165 | F13: ='NWC Schedule'!H25-('NWC Schedule'!H11+'NWC Schedule'!H14-'NWC Schedule'!H17) -> -8311.4419
A14: Status | B14: =IF(ABS(B13)<0.01,"PASS","FAIL") -> FAIL | C14: =IF(ABS(C13)<0.01,"PASS","FAIL") -> FAIL | D14: =IF(ABS(D13)<0.01,"PASS","FAIL") -> FAIL | E14: =IF(ABS(E13)<0.01,"PASS","FAIL") -> FAIL | F14: =IF(ABS(F13)<0.01,"PASS","FAIL") -> FAIL
A17: Retained Earnings Check | B17: ='Balance Sheet'!D49-('Balance Sheet'!C49+'Income Statement'!#REF!+'Cash Flow'!D24) -> #REF! | C17: ='Balance Sheet'!E49-('Balance Sheet'!D49+'Income Statement'!#REF!+'Cash Flow'!E24) -> #REF! | D17: ='Balance Sheet'!F49-('Balance Sheet'!E49+'Income Statement'!#REF!+'Cash Flow'!F24) -> #REF! | E17: ='Balance Sheet'!G49-('Balance Sheet'!F49+'Income Statement'!#REF!+'Cash Flow'!G24) -> #REF! | F17: ='Balance Sheet'!H49-('Balance Sheet'!G49+'Income Statement'!#REF!+'Cash Flow'!H24) -> #REF!
A18: Status | B18: =IF(ABS(B17)<0.01,"PASS","FAIL") -> #REF! | C18: =IF(ABS(C17)<0.01,"PASS","FAIL") -> #REF! | D18: =IF(ABS(D17)<0.01,"PASS","FAIL") -> #REF! | E18: =IF(ABS(E17)<0.01,"PASS","FAIL") -> #REF! | F18: =IF(ABS(F17)<0.01,"PASS","FAIL") -> #REF!
A21: OVERALL MODEL STATUS
B22: =IF(COUNTIF(B5:B16,"FAIL")=0,"ALL CHECKS PASS","REVIEW REQUIRED") -> REVIEW REQUIRED | C22: =IF(COUNTIF(C5:C16,"FAIL")=0,"ALL CHECKS PASS","REVIEW REQUIRED") -> REVIEW REQUIRED | D22: =IF(COUNTIF(D5:D16,"FAIL")=0,"ALL CHECKS PASS","REVIEW REQUIRED") -> REVIEW REQUIRED | E22: =IF(COUNTIF(E5:E16,"FAIL")=0,"ALL CHECKS PASS","REVIEW REQUIRED") -> REVIEW REQUIRED | F22: =IF(COUNTIF(F5:F16,"FAIL")=0,"ALL CHECKS PASS","REVIEW REQUIRED") -> REVIEW REQUIRED
